Workbook

Sheet BOM
A1: Category | B1: Component Name | C1: Value / Part No. | D1: Reference | E1: Footprint | F1: Qty | G1: Price per Unit (₦) | H1: Total (₦)
A2: Buzzer | B2: Buzzer | C2: Buzzer | D2: BZ1 | E2: Buzzer_Beeper:Buzzer_15x7.5RM7.6 | F2: 1 | G2: 600 | H2: =F2*G2 -> 600
A3: Capacitor | B3: 100nF | C3: 100nF | D3: C2,C11,C12,C19,C20,C23,C24 | E3: Capacitor_SMD:C_0805_2012Metric_Pad1.18x1.45mm_HandSolder | F3: 7 | G3: 200 | H3: =F3*G3 -> 1400
A4: Capacitor | B4: 104 | C4: 104 | D4: C6 | E4: Capacitor_SMD:C_0805_2012Metric | F4: 1 | G4: 200 | H4: =F4*G4 -> 200
A5: Capacitor | B5: 145J400V | C5: 145J400V | D5: C7 | E5: Capacitor_THT:C_Rect_L19.0mm_W6.0mm_P15.00mm_MKS4 | F5: 1 | G5: 500 | H5: =F5*G5 -> 500
A6: Capacitor | B6: 4.7uF/16V | C6: 4.7uF/16V | D6: C8,C13,C25 | E6: Capacitor_Tantalum_SMD:CP_EIA-3528-21_Kemet-B_HandSolder | F6: 3 | G6: 300 | H6: =F6*G6 -> 900
A7: Capacitor | B7: 10uF_16V | C7: 10uF_16V | D7: C9 | E7: Capacitor_THT:CP_Radial_D5.0mm_P2.00mm | F7: 1 | G7: 300 | H7: =F7*G7 -> 300
A8: Capacitor | B8: 470nF | C8: 470nF | D8: C10 | E8: Capacitor_SMD:C_0805_2012Metric_Pad1.18x1.45mm_HandSolder | F8: 1 | G8: 200 | H8: =F8*G8 -> 200
A9: Capacitor | B9: 470uF/25V | C9: 470uF/25V | D9: C14 | E9: Capacitor_SMD:CP_Elec_8x11.9 | F9: 1 | G9: 400 | H9: =F9*G9 -> 400
A10: Capacitor | B10: 680uF_35V | C10: 680uF_35V | D10: C15,C16 | E10: Capacitor_SMD:CP_Elec_10x12.5 | F10: 2 | G10: 400 | H10: =F10*G10 -> 800
A11: Capacitor | B11: 22pF | C11: 22pF | D11: C17,C18 | E11: Capacitor_SMD:C_0805_2012Metric_Pad1.18x1.45mm_HandSolder | F11: 2 | G11: 200 | H11: =F11*G11 -> 400
A12: Capacitor | B12: 220uF_16V | C12: 220uF_16V | D12: C21,C22 | E12: Capacitor_SMD:CP_Elec_6.3x7.7 | F12: 2 | G12: 300 | H12: =F12*G12 -> 600
A13: Diode | B13: 1N4007 | C13: 1N4007 | D13: D1 | E13: Diode_SMD:D_SMA | F13: 1 | G13: 100 | H13: =F13*G13 -> 100
... A20: Diode | B20: CMZ12 | C20: CMZ12 | D20: DZ1 | E20: Diode_SMD:D_SOD-123 | F20: 1 | G20: 100 | H20: =F20*G20 -> 100
A21: Connector / Terminal | B21: Screw_Terminal_01x03 | C21: Screw_Terminal_01x03 | D21: J1 | F21: 1 | G21: 400 | H21: =IF(OR(F18="",G18=""),"",F18*G18) -> 50
A22: Connector / Terminal | B22: Screw_Terminal_01x08 | C22: Screw_Terminal_01x08 | D22: J2 | F22: 1 | G22: 600 | H22: =IF(OR(F19="",G19=""),"",F19*G19) -> 200
A23: LCD SCREEN | B23: LCD SCREEN | C23: OLED SCREEN | D23: J3 | F23: 1 | H23: =IF(OR(F20="",G20=""),"",F20*G20) -> 100
A24: Connector / Terminal | B24: LOAD | C24: LOAD | D24: J4 | E24: TerminalBlock_Phoenix:TerminalBlock_Phoenix_MKDS-1,5-2_1x02_P5.00mm_Horizontal | F24: 1 | H24: =IF(OR(F21="",G21=""),"",F21*G21) -> 400
A25: Connector / Terminal | B25: 220VAC | C25: 220VAC | D25: J5 | E25: TerminalBlock_Phoenix:TerminalBlock_Phoenix_MKDS-1,5-2_1x02_P5.00mm_Horizontal | F25: 1 | H25: =IF(OR(F22="",G22=""),"",F22*G22) -> 600
A26: Connector / Terminal | B26: MPU6050 | C26: MPU6050 | D26: J6,J10 | E26: Connector_PinHeader_2.54mm:PinHeader_1x08_P2.54mm_Vertical | F26: 2 | H26: =IF(OR(F23="",G23=""),"",F23*G23)
A27: Connector / Terminal | B27: USB_C Conn | C27: USB_C Conn | D27: J8 | E27: Connector_PinHeader_2.54mm:PinHeader_1x04_P2.54mm_Vertical | F27: 1 | H27: =IF(OR(F24="",G24=""),"",F24*G24)
A28: Connector / Terminal | B28: 12VAC | C28: 12VAC | D28: J9 | E28: TerminalBlock_Phoenix:TerminalBlock_Phoenix_MKDS-1,5-2_1x02_P5.00mm_Horizontal | F28: 1 | H28: =IF(OR(F25="",G25=""),"",F25*G25)
A29: Connector / Terminal | D29: JP1 | E29: Jumper:SolderJumper-2_P1.3mm_Open_Pad1.0x1.5mm | F29: 1 | H29: =IF(OR(F26="",G26=""),"",F26*G26)
A30: Relay | B30: FINDER-36.11 | C30: FINDER-36.11 | D30: K1 | E30: Relay_THT:Relay_SPDT_Finder_36.11 | F30: 1 | H30: =IF(OR(F27="",G27=""),"",F27*G27)
A31: Inductor | B31: 33uH | C31: 33uH | D31: L1,L2 | E31: Inductor_SMD:L_12x12mm_H6mm | F31: 2 | H31: =IF(OR(F28="",G28=""),"",F28*G28)
A32: Optocoupler | B32: PC817XI | C32: PC817XI | D32: OC1,OC2 | E32: Package_DIP:DIP-4_W7.62mm_SMDSocket_SmallPads | F32: 2 | H32: =IF(OR(F29="",G29=""),"",F29*G29)
A33: Transistor | B33: UMH3N | C33: UMH3N | D33: Q1 | E33: Package_TO_SOT_SMD:SOT-363_SC-70-6 | F33: 1 | H33: =IF(OR(F30="",G30=""),"",F30*G30)
A34: Resistor | B34: 10k | C34: 10k | D34: R1,R5,R6,R7,R8,R9,R13,R14 | E34: Resistor_SMD:R_0805_2012Metric | F34: 8 | H34: =IF(OR(F31="",G31=""),"",F31*G31)
A35: Resistor | B35: 1M | C35: 1M | D35: R10 | E35: Resistor_THT:R_Axial_DIN0207_L6.3mm_D2.5mm_P7.62mm_Horizontal | F35: 1 | H35: =IF(OR(F32="",G32=""),"",F32*G32)
A36: Resistor | B36: 330R/2W | C36: 330R/2W | D36: R11 | E36: Resistor_THT:R_Axial_DIN0309_L9.0mm_D3.2mm_P20.32mm_Horizontal | F36: 1 | H36: =IF(OR(F33="",G33=""),"",F33*G33)
A37: Resistor | B37: 330R | C37: 330R | D37: R12,R15,R16 | E37: Resistor_SMD:R_0805_2012Metric | F37: 3 | H37: =IF(OR(F34="",G34=""),"",F34*G34)
A38: Switch / Encoder | B38: RotaryEncoder | C38: RotaryEncoder | D38: SW1 | E38: Connector_PinHeader_2.54mm:PinHeader_1x06_P2.54mm_Vertical | F38: 1 | H38: =IF(OR(F35="",G35=""),"",F35*G35)
A39: Switch / Encoder | B39: RESET | C39: RESET | D39: SW2 | E39: Button_Switch_SMD:SW_SPST_CK_KXT3 | F39: 1 | H39: =IF(OR(F36="",G36=""),"",F36*G36)
A40: Switch / Encoder | B40: FLASH | C40: FLASH | D40: SW3 | E40: Button_Switch_SMD:SW_SPST_CK_KXT3 | F40: 1 | H40: =IF(OR(F37="",G37=""),"",F37*G37)
A41: Sensor | B41: PT100 | C41: PT100 | D41: TH1 | F41: 1 | H41: =IF(OR(F38="",G38=""),"",F38*G38)
A42: IC / Module | B42: AMS1117-3.3 | C42: AMS1117-3.3 | D42: U1 | E42: Package_TO_SOT_SMD:SOT-223-3_TabPin2 | F42: 1 | H42: =IF(OR(F39="",G39=""),"",F39*G39)
A43: IC / Module | B43: ESP32-S3-WROOM-1U-N16R8 | C43: ESP32-S3-WROOM-1U-N16R8 | D43: U2 | E43: footprints:ESP32-S3-WROOM-1U-N16R8 | F43: 1 | H43: =IF(OR(F40="",G40=""),"",F40*G40)
A44: IC / Module | B44: LM2596S-3.3V | C44: LM2596S-3.3V | D44: U3 | E44: Package_TO_SOT_SMD:TO-263-5_TabPin6 | F44: 1 | H44: =IF(OR(F41="",G41=""),"",F41*G41)
A45: IC / Module | B45: LM2596S-5V | C45: LM2596S-5V | D45: U4 | E45: Package_TO_SOT_SMD:TO-263-5_TabPin6 | F45: 1 | H45: =IF(OR(F42="",G42=""),"",F42*G42)
A46: IC / Module | B46: CH340C | C46: CH340C | D46: U5 | E46: Package_SO:SOIC-16_3.9x9.9mm_P1.27mm | F46: 1 | H46: =IF(OR(F43="",G43=""),"",F43*G43)
...

Sheet Category Summary
A1: Category | B1: Component Lines | C1: Total Quantity | D1: Category Cost (₦)
A2: Buzzer | B2: =COUNTIF(BOM!A2:A47,A2) -> 1 | C2: =SUMIF(BOM!A2:A47,A2,BOM!F2:F47) -> 1 | D2: =SUMIF(BOM!A2:A47,A2,BOM!H2:H47) -> 600
A3: Capacitor | B3: =COUNTIF(BOM!A2:A47,A3) -> 10 | C3: =SUMIF(BOM!A2:A47,A3,BOM!F2:F47) -> 21 | D3: =SUMIF(BOM!A2:A47,A3,BOM!H2:H47) -> 5700
A4: Connector / Terminal | B4: =COUNTIF(BOM!A2:A47,A4) -> 8 | C4: =SUMIF(BOM!A2:A47,A4,BOM!F2:F47) -> 9 | D4: =SUMIF(BOM!A2:A47,A4,BOM!H2:H47) -> 1250
A5: Crystal / Oscillator | B5: =COUNTIF(BOM!A2:A47,A5) -> 1 | C5: =SUMIF(BOM!A2:A47,A5,BOM!F2:F47) -> 1 | D5: =SUMIF(BOM!A2:A47,A5,BOM!H2:H47) -> 0
A6: Diode / LED | B6: =COUNTIF(BOM!A2:A47,A6) -> 2 | C6: =SUMIF(BOM!A2:A47,A6,BOM!F2:F47) -> 3 | D6: =SUMIF(BOM!A2:A47,A6,BOM!H2:H47) -> 150
A7: IC / Module | B7: =COUNTIF(BOM!A2:A47,A7) -> 5 | C7: =SUMIF(BOM!A2:A47,A7,BOM!F2:F47) -> 5 | D7: =SUMIF(BOM!A2:A47,A7,BOM!H2:H47) -> 0
A8: Inductor | B8: =COUNTIF(BOM!A2:A47,A8) -> 1 | C8: =SUMIF(BOM!A2:A47,A8,BOM!F2:F47) -> 2 | D8: =SUMIF(BOM!A2:A47,A8,BOM!H2:H47) -> 0
A9: Optocoupler | B9: =COUNTIF(BOM!A2:A47,A9) -> 1 | C9: =SUMIF(BOM!A2:A47,A9,BOM!F2:F47) -> 2 | D9: =SUMIF(BOM!A2:A47,A9,BOM!H2:H47) -> 0
A10: Relay | B10: =COUNTIF(BOM!A2:A47,A10) -> 1 | C10: =SUMIF(BOM!A2:A47,A10,BOM!F2:F47) -> 1 | D10: =SUMIF(BOM!A2:A47,A10,BOM!H2:H47) -> 0
A11: Resistor | B11: =COUNTIF(BOM!A2:A47,A11) -> 4 | C11: =SUMIF(BOM!A2:A47,A11,BOM!F2:F47) -> 13 | D11: =SUMIF(BOM!A2:A47,A11,BOM!H2:H47) -> 0
A12: Sensor | B12: =COUNTIF(BOM!A2:A47,A12) -> 1 | C12: =SUMIF(BOM!A2:A47,A12,BOM!F2:F47) -> 1 | D12: =SUMIF(BOM!A2:A47,A12,BOM!H2:H47) -> 0
A13: Switch / Encoder | B13: =COUNTIF(BOM!A2:A47,A13) -> 3 | C13: =SUMIF(BOM!A2:A47,A13,BOM!F2:F47) -> 3 | D13: =SUMIF(BOM!A2:A47,A13,BOM!H2:H47) -> 0
A14: Transistor | B14: =COUNTIF(BOM!A2:A47,A14) -> 1 | C14: =SUMIF(BOM!A2:A47,A14,BOM!F2:F47) -> 1 | D14: =SUMIF(BOM!A2:A47,A14,BOM!H2:H47) -> 0
A15: GRAND TOTAL | B15: =SUM(B2:B14) -> 39 | C15: =SUM(C2:C14) -> 63 | D15: =SUM(D2:D14) -> 7700
